Workbook

Sheet Operations Overview
A1: BLOOM & CO. | OPERATIONS OVERVIEW
A2: Order management • Customer records • Fulfillment monitoring
A4: TOTAL ORDERS | D4: GROSS ORDER VALUE | G4: ORDERS TO FOLLOW UP
A5: =COUNTA('Order Register'!A2:A200) -> 50 | D5: =SUM('Order Register'!H2:H200) -> 53824 | G5: =COUNTIF('Order Register'!L2:L200,"Check payment")+COUNTIF('Order Register'!L2:L200,"Prepare order")+COUNTIF('Order Register'!L2:L200,"Fulfill order") -> 14
D7: PAID ORDER VALUE
D8: =SUMIF('Order Register'!I2:I1000,"Paid",'Order Register'!H2:H1000) -> 41771
A10: FULFILLMENT PIPELINE | E10: PAYMENT MONITORING
A11: Pending | B11: =COUNTIF('Order Register'!J2:J200,A11) -> 7 | E11: Paid | F11: =COUNTIF('Order Register'!I2:I200,E11) -> 39
A12: Processing | B12: =COUNTIF('Order Register'!J2:J200,A12) -> 7 | E12: Pending | F12: =COUNTIF('Order Register'!I2:I200,E12) -> 7
A13: Shipped | B13: =COUNTIF('Order Register'!J2:J200,A13) -> 7 | E13: Refunded | F13: =COUNTIF('Order Register'!I2:I200,E13) -> 4
A14: Delivered | B14: =COUNTIF('Order Register'!J2:J200,A14) -> 22 | E14: Failed | F14: =COUNTIF('Order Register'!I2:I200,E14) -> 0
A15: Cancelled | B15: =COUNTIF('Order Register'!J2:J200,A15) -> 7
A18: INTERNAL OPERATIONS NOTES
A19: Fulfillment statuses are updated manually in the Order Register; dashboard counts and totals update using formulas.
A20: Portfolio demonstration only • All customer details, orders, and tracking numbers are fictional.

Sheet Order Register
A1: Order ID | B1: Order Date | C1: Customer ID | D1: Customer Name | E1: Product | F1: Qty | G1: Unit Price (PHP) | H1: Order Total (PHP) | I1: Payment Status | J1: Fulfillment Status | K1: Tracking Number | L1: Action Required
A2: ORD-1001 | B2: 46296 | C2: CUS-001 | D2: Maria Santos | E2: Oversized Tee | F2: 1 | G2: 450 | H2: =IF(OR(F2="",G2=""),"",F2*G2) -> 450 | I2: Paid | J2: Delivered | K2: JT424234107 | L2: =IF(A2="","",IF(J2="Cancelled","Closed",IF(I2="Pending","Check payment",IF(J2="Pending","Prepare order",IF(J2="Processing","Fulfill order",IF(J2="Shipped","Monitor delivery","Complete")))))) -> Complete
A3: ORD-1002 | B3: 46297 | C3: CUS-008 | D3: Carlo Torres | E3: Canvas Tote | F3: 2 | G3: 299 | H3: =IF(OR(F3="",G3=""),"",F3*G3) -> 598 | I3: Paid | J3: Shipped | K3: JT373107924 | L3: =IF(A3="","",IF(J3="Cancelled","Closed",IF(I3="Pending","Check payment",IF(J3="Pending","Prepare order",IF(J3="Processing","Fulfill order",IF(J3="Shipped","Monitor delivery","Complete")))))) -> Monitor delivery
A4: ORD-1003 | B4: 46298 | C4: CUS-015 | D4: Ella Castillo | E4: Classic Hoodie | F4: 3 | G4: 899 | H4: =IF(OR(F4="",G4=""),"",F4*G4) -> 2697 | I4: Paid | J4: Processing | L4: =IF(A4="","",IF(J4="Cancelled","Closed",IF(I4="Pending","Check payment",IF(J4="Pending","Prepare order",IF(J4="Processing","Fulfill order",IF(J4="Shipped","Monitor delivery","Complete")))))) -> Fulfill order
A5: ORD-1004 | B5: 46299 | C5: CUS-022 | D5: Adrian Gomez | E5: Baseball Cap | F5: 1 | G5: 350 | H5: =IF(OR(F5="",G5=""),"",F5*G5) -> 350 | I5: Pending | J5: Pending | L5: =IF(A5="","",IF(J5="Cancelled","Closed",IF(I5="Pending","Check payment",IF(J5="Pending","Prepare order",IF(J5="Processing","Fulfill order",IF(J5="Shipped","Monitor delivery","Complete")))))) -> Check payment
A6: ORD-1005 | B6: 46300 | C6: CUS-029 | D6: Lea Luna | E6: Cargo Pants | F6: 2 | G6: 750 | H6: =IF(OR(F6="",G6=""),"",F6*G6) -> 1500 | I6: Paid | J6: Delivered | K6: JT955028465 | L6: =IF(A6="","",IF(J6="Cancelled","Closed",IF(I6="Pending","Check payment",IF(J6="Pending","Prepare order",IF(J6="Processing","Fulfill order",IF(J6="Shipped","Monitor delivery","Complete")))))) -> Complete
A7: ORD-1006 | B7: 46301 | C7: CUS-006 | D7: Paolo Dela Cruz | E7: Everyday Shirt | F7: 3 | G7: 520 | H7: =IF(OR(F7="",G7=""),"",F7*G7) -> 1560 | I7: Paid | J7: Delivered | K7: JT696896241 | L7: =IF(A7="","",IF(J7="Cancelled","Closed",IF(I7="Pending","Check payment",IF(J7="Pending","Prepare order",IF(J7="Processing","Fulfill order",IF(J7="Shipped","Monitor delivery","Complete")))))) -> Complete
A8: ORD-1007 | B8: 46302 | C8: CUS-013 | D8: Bianca Navarro | E8: Crossbody Bag | F8: 1 | G8: 640 | H8: =IF(OR(F8="",G8=""),"",F8*G8) -> 640 | I8: Refunded | J8: Cancelled | L8: =IF(A8="","",IF(J8="Cancelled","Closed",IF(I8="Pending","Check payment",IF(J8="Pending","Prepare order",IF(J8="Processing","Fulfill order",IF(J8="Shipped","Monitor delivery","Complete")))))) -> Closed
A9: ORD-1008 | B9: 46303 | C9: CUS-020 | D9: Luis Morales | E9: Linen Shorts | F9: 2 | G9: 490 | H9: =IF(OR(F9="",G9=""),"",F9*G9) -> 980 | I9: Paid | J9: Delivered | K9: JT846616491 | L9: =IF(A9="","",IF(J9="Cancelled","Closed",IF(I9="Pending","Check payment",IF(J9="Pending","Prepare order",IF(J9="Processing","Fulfill order",IF(J9="Shipped","Monitor delivery","Complete")))))) -> Complete
A10: ORD-1009 | B10: 46304 | C10: CUS-027 | D10: Erika Valdez | E10: Oversized Tee | F10: 3 | G10: 450 | H10: =IF(OR(F10="",G10=""),"",F10*G10) -> 1350 | I10: Paid | J10: Shipped | K10: JT840388786 | L10: =IF(A10="","",IF(J10="Cancelled","Closed",IF(I10="Pending","Check payment",IF(J10="Pending","Prepare order",IF(J10="Processing","Fulfill order",IF(J10="Shipped","Monitor delivery","Complete")))))) -> Monitor delivery
A11: ORD-1010 | B11: 46305 | C11: CUS-004 | D11: Mark Rivera | E11: Canvas Tote | F11: 1 | G11: 299 | H11: =IF(OR(F11="",G11=""),"",F11*G11) -> 299 | I11: Paid | J11: Processing | L11: =IF(A11="","",IF(J11="Cancelled","Closed",IF(I11="Pending","Check payment",IF(J11="Pending","Prepare order",IF(J11="Processing","Fulfill order",IF(J11="Shipped","Monitor delivery","Complete")))))) -> Fulfill order
A12: ORD-1011 | B12: 46306 | C12: CUS-011 | D12: Grace Aquino | E12: Classic Hoodie | F12: 2 | G12: 899 | H12: =IF(OR(F12="",G12=""),"",F12*G12) -> 1798 | I12: Pending | J12: Pending | L12: =IF(A12="","",IF(J12="Cancelled","Closed",IF(I12="Pending","Check payment",IF(J12="Pending","Prepare order",IF(J12="Processing","Fulfill order",IF(J12="Shipped","Monitor delivery","Complete")))))) -> Check payment
A13: ORD-1012 | B13: 46307 | C13: CUS-018 | D13: Joshua Sy | E13: Baseball Cap | F13: 3 | G13: 350 | H13: =IF(OR(F13="",G13=""),"",F13*G13) -> 1050 | I13: Paid | J13: Delivered | K13: JT188477572 | L13: =IF(A13="","",IF(J13="Cancelled","Closed",IF(I13="Pending","Check payment",IF(J13="Pending","Prepare order",IF(J13="Processing","Fulfill order",IF(J13="Shipped","Monitor delivery","Complete")))))) -> Complete
A14: ORD-1013 | B14: 46308 | C14: CUS-025 | D14: Faith Pascual | E14: Cargo Pants | F14: 1 | G14: 750 | H14: =IF(OR(F14="",G14=""),"",F14*G14) -> 750 | I14: Paid | J14: Delivered | K14: JT421928641 | L14: =IF(A14="","",IF(J14="Cancelled","Closed",IF(I14="Pending","Check payment",IF(J14="Pending","Prepare order",IF(J14="Processing","Fulfill order",IF(J14="Shipped","Monitor delivery","Complete")))))) -> Complete
A15: ORD-1014 | B15: 46309 | C15: CUS-002 | D15: John Reyes | E15: Everyday Shirt | F15: 2 | G15: 520 | H15: =IF(OR(F15="",G15=""),"",F15*G15) -> 1040 | I15: Paid | J15: Cancelled | L15: =IF(A15="","",IF(J15="Cancelled","Closed",IF(I15="Pending","Check payment",IF(J15="Pending","Prepare order",IF(J15="Processing","Fulfill order",IF(J15="Shipped","Monitor delivery","Complete")))))) -> Closed
A16: ORD-1015 | B16: 46310 | C16: CUS-009 | D16: Jasmine Flores | E16: Crossbody Bag | F16: 3 | G16: 640 | H16: =IF(OR(F16="",G16=""),"",F16*G16) -> 1920 | I16: Paid | J16: Delivered | K16: JT590248392 | L16: =IF(A16="","",IF(J16="Cancelled","Closed",IF(I16="Pending","Check payment",IF(J16="Pending","Prepare order",IF(J16="Processing","Fulfill order",IF(J16="Shipped","Monitor delivery","Complete")))))) -> Complete
A17: ORD-1016 | B17: 46311 | C17: CUS-016 | D17: Rafael Domingo | E17: Linen Shorts | F17: 1 | G17: 490 | H17: =IF(OR(F17="",G17=""),"",F17*G17) -> 490 | I17: Paid | J17: Shipped | K17: JT597629994 | L17: =IF(A17="","",IF(J17="Cancelled","Closed",IF(I17="Pending","Check payment",IF(J17="Pending","Prepare order",IF(J17="Processing","Fulfill order",IF(J17="Shipped","Monitor delivery","Complete")))))) -> Monitor delivery
A18: ORD-1017 | B18: 46312 | C18: CUS-023 | D18: Isabel Fernandez | E18: Oversized Tee | F18: 2 | G18: 450 | H18: =IF(OR(F18="",G18=""),"",F18*G18) -> 900 | I18: Paid | J18: Processing | L18: =IF(A18="","",IF(J18="Cancelled","Closed",IF(I18="Pending","Check payment",IF(J18="Pending","Prepare order",IF(J18="Processing","Fulfill order",IF(J18="Shipped","Monitor delivery","Complete")))))) -> Fulfill order
A19: ORD-1018 | B19: 46313 | C19: CUS-030 | D19: Vincent Chua | E19: Canvas Tote | F19: 3 | G19: 299 | H19: =IF(OR(F19="",G19=""),"",F19*G19) -> 897 | I19: Pending | J19: Pending | L19: =IF(A19="","",IF(J19="Cancelled","Closed",IF(I19="Pending","Check payment",IF(J19="Pending","Prepare order",IF(J19="Processing","Fulfill order",IF(J19="Shipped","Monitor delivery","Complete")))))) -> Check payment
A20: ORD-1019 | B20: 46314 | C20: CUS-007 | D20: Nicole Mendoza | E20: Classic Hoodie | F20: 1 | G20: 899 | H20: =IF(OR(F20="",G20=""),"",F20*G20) -> 899 | I20: Paid | J20: Delivered | K20: JT405764635 | L20: =IF(A20="","",IF(J20="Cancelled","Closed",IF(I20="Pending","Check payment",IF(J20="Pending","Prepare order",IF(J20="Processing","Fulfill order",IF(J20="Shipped","Monitor delivery","Complete")))))) -> Complete
A21: ORD-1020 | B21: 46315 | C21: CUS-014 | D21: Kevin Lim | E21: Baseball Cap | F21: 2 | G21: 350 | H21: =IF(OR(F21="",G21=""),"",F21*G21) -> 700 | I21: Paid | J21: Delivered | K21: JT651064777 | L21: =IF(A21="","",IF(J21="Cancelled","Closed",IF(I21="Pending","Check payment",IF(J21="Pending","Prepare order",IF(J21="Processing","Fulfill order",IF(J21="Shipped","Monitor delivery","Complete")))))) -> Complete
A22: ORD-1021 | B22: 46316 | C22: CUS-021 | D22: Trisha Salazar | E22: Cargo Pants | F22: 3 | G22: 750 | H22: =IF(OR(F22="",G22=""),"",F22*G22) -> 2250 | I22: Refunded | J22: Cancelled | L22: =IF(A22="","",IF(J22="Cancelled","Closed",IF(I22="Pending","Check payment",IF(J22="Pending","Prepare order",IF(J22="Processing","Fulfill order",IF(J22="Shipped","Monitor delivery","Complete")))))) -> Closed
A23: ORD-1022 | B23: 46317 | C23: CUS-028 | D23: Gabriel Soriano | E23: Everyday Shirt | F23: 1 | G23: 520 | H23: =IF(OR(F23="",G23=""),"",F23*G23) -> 520 | I23: Paid | J23: Delivered | K23: JT226006770 | L23: =IF(A23="","",IF(J23="Cancelled","Closed",IF(I23="Pending","Check payment",IF(J23="Pending","Prepare order",IF(J23="Processing","Fulfill order",IF(J23="Shipped","Monitor delivery","Complete")))))) -> Complete
A24: ORD-1023 | B24: 46318 | C24: CUS-005 | D24: Sofia Garcia | E24: Crossbody Bag | F24: 2 | G24: 640 | H24: =IF(OR(F24="",G24=""),"",F24*G24) -> 1280 | I24: Paid | J24: Shipped | K24: JT729051750 | L24: =IF(A24="","",IF(J24="Cancelled","Closed",IF(I24="Pending","Check payment",IF(J24="Pending","Prepare order",IF(J24="Processing","Fulfill order",IF(J24="Shipped","Monitor delivery","Complete")))))) -> Monitor delivery
A25: ORD-1024 | B25: 46319 | C25: CUS-012 | D25: Miguel Bautista | E25: Linen Shorts | F25: 3 | G25: 490 | H25: =IF(OR(F25="",G25=""),"",F25*G25) -> 1470 | I25: Paid | J25: Processing | L25: =IF(A25="","",IF(J25="Cancelled","Closed",IF(I25="Pending","Check payment",IF(J25="Pending","Prepare order",IF(J25="Processing","Fulfill order",IF(J25="Shipped","Monitor delivery","Complete")))))) -> Fulfill order
A26: ORD-1025 | B26: 46320 | C26: CUS-019 | D26: Hannah Tan | E26: Oversized Tee | F26: 1 | G26: 450 | H26: =IF(OR(F26="",G26=""),"",F26*G26) -> 450 | I26: Pending | J26: Pending | L26: =IF(A26="","",IF(J26="Cancelled","Closed",IF(I26="Pending","Check payment",IF(J26="Pending","Prepare order",IF(J26="Processing","Fulfill order",IF(J26="Shipped","Monitor delivery","Complete")))))) -> Check payment
A27: ORD-1026 | B27: 46321 | C27: CUS-026 | D27: Noel Mercado | E27: Canvas Tote | F27: 2 | G27: 299 | H27: =IF(OR(F27="",G27=""),"",F27*G27) -> 598 | I27: Paid | J27: Delivered | K27: JT124150170 | L27: =IF(A27="","",IF(J27="Cancelled","Closed",IF(I27="Pending","Check payment",IF(J27="Pending","Prepare order",IF(J27="Processing","Fulfill order",IF(J27="Shipped","Monitor delivery","Complete")))))) -> Complete
A28: ORD-1027 | B28: 46322 | C28: CUS-003 | D28: Angela Cruz | E28: Classic Hoodie | F28: 3 | G28: 899 | H28: =IF(OR(F28="",G28=""),"",F28*G28) -> 2697 | I28: Paid | J28: Delivered | K28: JT405982447 | L28: =IF(A28="","",IF(J28="Cancelled","Closed",IF(I28="Pending","Check payment",IF(J28="Pending","Prepare order",IF(J28="Processing","Fulfill order",IF(J28="Shipped","Monitor delivery","Complete")))))) -> Complete
A29: ORD-1028 | B29: 46323 | C29: CUS-010 | D29: Daniel Ramos | E29: Baseball Cap | F29: 1 | G29: 350 | H29: =IF(OR(F29="",G29=""),"",F29*G29) -> 350 | I29: Paid | J29: Cancelled | L29: =IF(A29="","",IF(J29="Cancelled","Closed",IF(I29="Pending","Check payment",IF(J29="Pending","Prepare order",IF(J29="Processing","Fulfill order",IF(J29="Shipped","Monitor delivery","Complete")))))) -> Closed
A30: ORD-1029 | B30: 46296 | C30: CUS-017 | D30: Camille Villanueva | E30: Cargo Pants | F30: 2 | G30: 750 | H30: =IF(OR(F30="",G30=""),"",F30*G30) -> 1500 | I30: Paid | J30: Delivered | K30: JT332572512 | L30: =IF(A30="","",IF(J30="Cancelled","Closed",IF(I30="Pending","Check payment",IF(J30="Pending","Prepare order",IF(J30="Processing","Fulfill order",IF(J30="Shipped","Monitor delivery","Complete")))))) -> Complete
A31: ORD-1030 | B31: 46297 | C31: CUS-024 | D31: Marco Ocampo | E31: Everyday Shirt | F31: 3 | G31: 520 | H31: =IF(OR(F31="",G31=""),"",F31*G31) -> 1560 | I31: Paid | J31: Shipped | K31: JT930398002 | L31: =IF(A31="","",IF(J31="Cancelled","Closed",IF(I31="Pending","Check payment",IF(J31="Pending","Prepare order",IF(J31="Processing","Fulfill order",IF(J31="Shipped","Monitor delivery","Complete")))))) -> Monitor delivery
A32: ORD-1031 | B32: 46298 | C32: CUS-001 | D32: Maria Santos | E32: Crossbody Bag | F32: 1 | G32: 640 | H32: =IF(OR(F32="",G32=""),"",F32*G32) -> 640 | I32: Paid | J32: Processing | L32: =IF(A32="","",IF(J32="Cancelled","Closed",IF(I32="Pending","Check payment",IF(J32="Pending","Prepare order",IF(J32="Processing","Fulfill order",IF(J32="Shipped","Monitor delivery","Complete")))))) -> Fulfill order
A33: ORD-1032 | B33: 46299 | C33: CUS-008 | D33: Carlo Torres | E33: Linen Shorts | F33: 2 | G33: 490 | H33: =IF(OR(F33="",G33=""),"",F33*G33) -> 980 | I33: Pending | J33: Pending | L33: =IF(A33="","",IF(J33="Cancelled","Closed",IF(I33="Pending","Check payment",IF(J33="Pending","Prepare order",IF(J33="Processing","Fulfill order",IF(J33="Shipped","Monitor delivery","Complete")))))) -> Check payment
A34: ORD-1033 | B34: 46300 | C34: CUS-015 | D34: Ella Castillo | E34: Oversized Tee | F34: 3 | G34: 450 | H34: =IF(OR(F34="",G34=""),"",F34*G34) -> 1350 | I34: Paid | J34: Delivered | K34: JT612859897 | L34: =IF(A34="","",IF(J34="Cancelled","Closed",IF(I34="Pending","Check payment",IF(J34="Pending","Prepare order",IF(J34="Processing","Fulfill order",IF(J34="Shipped","Monitor delivery","Complete")))))) -> Complete
A35: ORD-1034 | B35: 46301 | C35: CUS-022 | D35: Adrian Gomez | E35: Canvas Tote | F35: 1 | G35: 299 | H35: =IF(OR(F35="",G35=""),"",F35*G35) -> 299 | I35: Paid | J35: Delivered | K35: JT695144266 | L35: =IF(A35="","",IF(J35="Cancelled","Closed",IF(I35="Pending","Check payment",IF(J35="Pending","Prepare order",IF(J35="Processing","Fulfill order",IF(J35="Shipped","Monitor delivery","Complete")))))) -> Complete
A36: ORD-1035 | B36: 46302 | C36: CUS-029 | D36: Lea Luna | E36: Classic Hoodie | F36: 2 | G36: 899 | H36: =IF(OR(F36="",G36=""),"",F36*G36) -> 1798 | I36: Refunded | J36: Cancelled | L36: =IF(A36="","",IF(J36="Cancelled","Closed",IF(I36="Pending","Check payment",IF(J36="Pending","Prepare order",IF(J36="Processing","Fulfill order",IF(J36="Shipped","Monitor delivery","Complete")))))) -> Closed
A37: ORD-1036 | B37: 46303 | C37: CUS-006 | D37: Paolo Dela Cruz | E37: Baseball Cap | F37: 3 | G37: 350 | H37: =IF(OR(F37="",G37=""),"",F37*G37) -> 1050 | I37: Paid | J37: Delivered | K37: JT682636164 | L37: =IF(A37="","",IF(J37="Cancelled","Closed",IF(I37="Pending","Check payment",IF(J37="Pending","Prepare order",IF(J37="Processing","Fulfill order",IF(J37="Shipped","Monitor delivery","Complete")))))) -> Complete
A38: ORD-1037 | B38: 46304 | C38: CUS-013 | D38: Bianca Navarro | E38: Cargo Pants | F38: 1 | G38: 750 | H38: =IF(OR(F38="",G38=""),"",F38*G38) -> 750 | I38: Paid | J38: Shipped | K38: JT835632515 | L38: =IF(A38="","",IF(J38="Cancelled","Closed",IF(I38="Pending","Check payment",IF(J38="Pending","Prepare order",IF(J38="Processing","Fulfill order",IF(J38="Shipped","Monitor delivery","Complete")))))) -> Monitor delivery
A39: ORD-1038 | B39: 46305 | C39: CUS-020 | D39: Luis Morales | E39: Everyday Shirt | F39: 2 | G39: 520 | H39: =IF(OR(F39="",G39=""),"",F39*G39) -> 1040 | I39: Paid | J39: Processing | L39: =IF(A39="","",IF(J39="Cancelled","Closed",IF(I39="Pending","Check payment",IF(J39="Pending","Prepare order",IF(J39="Processing","Fulfill order",IF(J39="Shipped","Monitor delivery","Complete")))))) -> Fulfill order
A40: ORD-1039 | B40: 46306 | C40: CUS-027 | D40: Erika Valdez | E40: Crossbody Bag | F40: 3 | G40: 640 | H40: =IF(OR(F40="",G40=""),"",F40*G40) -> 1920 | I40: Pending | J40: Pending | L40: =IF(A40="","",IF(J40="Cancelled","Closed",IF(I40="Pending","Check payment",IF(J40="Pending","Prepare order",IF(J40="Processing","Fulfill order",IF(J40="Shipped","Monitor delivery","Complete")))))) -> Check payment
...

Sheet Customer Directory
A1: Customer ID | B1: Customer Name | C1: Email Address | D1: Mobile Number | E1: City | F1: Record Status | H1: CUSTOMER DIRECTORY
A2: CUS-001 | B2: Maria Santos | C2: maria.santos@example.com | D2: 0993-591-5541 | E2: Manila | F2: Review
A3: CUS-002 | B3: John Reyes | C3: john.reyes@example.com | D3: 0946-301-2211 | E3: Cebu City | F3: Active | H3: Total customers | I3: =COUNTA(A2:A150) -> 30
A4: CUS-003 | B4: Angela Cruz | C4: angela.cruz@example.com | D4: 0918-360-9840 | E4: Davao City | F4: Active | H4: Active records | I4: =COUNTIF(F2:F150,"Active") -> 26
A5: CUS-004 | B5: Mark Rivera | C5: mark.rivera@example.com | D5: 0952-358-7100 | E5: Santa Rosa | F5: Active | H5: Review required | I5: =COUNTIF(F2:F150,"Review") -> 4
A6: CUS-005 | B6: Sofia Garcia | C6: sofia.garcia@example.com | D6: 0961-287-5060 | E6: Batangas City | F6: Active
A7: CUS-006 | B7: Paolo Dela Cruz | C7: paolo.delacruz@example.com | D7: 0940-602-2168 | E7: Quezon City | F7: Active
A8: CUS-007 | B8: Nicole Mendoza | C8: nicole.mendoza@example.com | D8: 0991-686-2289 | E8: Makati | F8: Active
A9: CUS-008 | B9: Carlo Torres | C9: carlo.torres@example.com | D9: 0988-958-7966 | E9: Pasig | F9: Active
A10: CUS-009 | B10: Jasmine Flores | C10: jasmine.flores@example.com | D10: 0963-857-1863 | E10: Taguig | F10: Active
A11: CUS-010 | B11: Daniel Ramos | C11: daniel.ramos@example.com | D11: 0994-550-6729 | E11: Calamba | F11: Review
A12: CUS-011 | B12: Grace Aquino | C12: grace.aquino@example.com | D12: 0911-965-8839 | E12: Manila | F12: Active
A13: CUS-012 | B13: Miguel Bautista | C13: miguel.bautista@example.com | D13: 0942-240-6535 | E13: Cebu City | F13: Active
A14: CUS-013 | B14: Bianca Navarro | C14: bianca.navarro@example.com | D14: 0988-765-4726 | E14: Davao City | F14: Active
A15: CUS-014 | B15: Kevin Lim | C15: kevin.lim@example.com | D15: 0977-244-2617 | E15: Santa Rosa | F15: Active
A16: CUS-015 | B16: Ella Castillo | C16: ella.castillo@example.com | D16: 0960-869-5948 | E16: Batangas City | F16: Active
A17: CUS-016 | B17: Rafael Domingo | C17: rafael.domingo@example.com | D17: 0914-894-9691 | E17: Quezon City | F17: Active
... A31: CUS-030 | B31: Vincent Chua | C31: vincent.chua@example.com | D31: 0960-451-2872 | E31: Calamba | F31: Active
